<?xml version="1.0"?>

<robot name="roboservo">

  <material name="black">
    <color rgba="0.0 0.0 0.0 1.0"/>
  </material>
  <material name="white">
    <color rgba="1.0 1.0 1.0 1.0"/>
  </material>

  <link name="base_link"/>

  <link name="body_link">
    <visual>
      <geometry>
        <cylinder radius="0.04" length="0.1"/>
      </geometry>
      <material name="black"/>
    </visual>
  </link>
  <joint name="body_joint" type="fixed">
    <parent link="base_link"/>
    <child link="body_link"/>
    <origin xyz="0.0 0.0 0.04" rpy="0.0 1.571 0.0"/>
  </joint>

  <link name="mount_link">
    <visual>
      <geometry>
        <cylinder radius="0.03" length="0.01"/>
      </geometry>
      <material name="white"/>
    </visual>
  </link>
  <joint name="roboservo_1" type="continuous">
    <parent link="body_link"/>
    <child link="mount_link"/>
    <origin xyz="0.0 0.0 0.055" rpy="0.0 0.0 0.0"/>
    <axis xyz="0.0 0.0 1.0"/>
  </joint>

  <link name="mark_link">
    <visual>
      <geometry>
        <cylinder radius="0.002" length="0.001"/>
      </geometry>
      <material name="black"/>
    </visual>
  </link>
  <joint name="roboservo_2" type="continuous">
    <parent link="mount_link"/>
    <child link="mark_link"/>
    <origin xyz="-0.025 0.0 0.005" rpy="0.0 0.0 0.0"/>
  </joint>

</robot>
